import { Context } from '../context';
import { ContextBuilder } from '../context-builder';
import { Meta } from '../base';
import { CustomValidation } from './custom-validation';

let context: Context;
let validator: jest.Mock;
let validation: CustomValidation;
const meta: Meta = {
  req: { cookies: { foo: 'bar' } },
  location: 'cookies',
  path: 'foo',
};

beforeEach(() => {
  context = new ContextBuilder().setFields(['foo']).setLocations(['cookies']).build();
  jest.spyOn(context, 'addError');

  validator = jest.fn();
  validation = new CustomValidation(validator, false, { customOption: true });
  validation.message = 'nope';
});

// There are 4 tests that are pretty much the same with just small variations among them.
// So it's made reusable here
const createSyncTest = (options: { returnValue: any; addsError: boolean }) => async () => {
  validator.mockReturnValue(options.returnValue);
  await validation.run(context, 'bar', meta);
  if (options.addsError) {
    expect(context.addError).toHaveBeenCalledWith(validation.message, 'bar', meta);
  } else {
    expect(context.addError).not.toHaveBeenCalled();
  }
};

it('calls validator with value, meta and options', async () => {
  await validation.run(context, 'bar', meta);
  expect(validator).toBeCalledWith('bar', meta, { customOption: true });
});

describe('when not negated', () => {
  it(
    'adds error if validator returns falsy',
    createSyncTest({ returnValue: false, addsError: true }),
  );

  it(
    'does not add error if validator returns truthy',
    createSyncTest({ returnValue: true, addsError: false }),
  );

  it('adds error if validator throws', async () => {
    // Thrown error's message
    validator.mockImplementation(() => {
      throw new Error('boom');
    });
    await validation.run(context, 'bar', meta);
    expect(context.addError).toHaveBeenCalledWith('boom', 'bar', meta);

    // Validation's message
    validator.mockImplementation(() => {
      throw new Error();
    });
    await validation.run(context, 'bar', meta);
    expect(context.addError).toHaveBeenCalledWith(validation.message, 'bar', meta);
  });

  it('adds error if validator returns a promise that rejects', async () => {
    // Rejection cause's message
    validator.mockRejectedValue('a bomb');
    await validation.run(context, 'bar', meta);
    expect(context.addError).toHaveBeenCalledWith('a bomb', 'bar', meta);

    // Validation's message
    validator.mockRejectedValue(undefined);
    await validation.run(context, 'bar', meta);
    expect(context.addError).toHaveBeenCalledWith(validation.message, 'bar', meta);
  });

  it('does not add error if validator returns a promise that resolves', async () => {
    validator.mockResolvedValue(true);
    await validation.run(context, 'bar', meta);
    expect(context.addError).not.toHaveBeenCalled();
  });
});

describe('when negated', () => {
  beforeEach(() => {
    validation = new CustomValidation(validator, true);
    validation.message = 'nope';
  });

  it(
    'adds error if validator returns truthy',
    createSyncTest({ returnValue: true, addsError: true }),
  );

  it(
    'does not add error if validator returns falsy',
    createSyncTest({ returnValue: false, addsError: false }),
  );

  it('does not add error if validator throws', async () => {
    validator.mockImplementation(() => {
      throw new Error('boom');
    });
    await validation.run(context, 'bar', meta);
    expect(context.addError).not.toHaveBeenCalled();
  });

  it('does not add error if validator returns a promise that rejects', async () => {
    validator.mockRejectedValue('a bomb');
    await validation.run(context, 'bar', meta);
    expect(context.addError).not.toHaveBeenCalled();
  });

  it('adds error if validator returns a promise that resolves', async () => {
    validator.mockResolvedValue(true);
    await validation.run(context, 'bar', meta);
    expect(context.addError).toHaveBeenCalledWith(validation.message, 'bar', meta);
  });
});
